Workbook

Sheet Coordenadas
A1: Jordania | B1: HTU | C1: 31.9800,35.8540
A2: Alemania | B2: Bonn-Rhein-Sieg | C2: 50.78108, 7.18062
A3: Chile | B3: UMAG | C3: -53.1441,-70.9306
A4: Chile | B4: Duoc UC - Plaza Norte | C4: -33.3661, -70.6787
A5: Colombia | B5: Universidad Libre | C5: 4.6127,-74.0705
A6: Francia | B6: ESAIP | C6: 47.4700,-0.5040
A7: Georgia | B7: Business and Technology University | C7: 41.7150,44.7800
A8: Italia | B8: Unimore | C8: 44.6450,10.9250
A9: Italia | B9: Udine | C9: 46.0635,13.2372
A10: Italia | B10: Pol. Milan | C10: 45.4781,9.2284
A11: Italia | B11: Degli Studi di Sassari | C11: 40.7242,8.5600
A12: Jordania | B12: University of Petra | C12: 31.7326,35.8299
... A22: Turquía | B22: Kadir Has University | C22: 41.0254,28.9470

Sheet 2025-2026
A1: Asignatura | B1: Estudiante | C1: Origen | D1: Universidad Origen | E1: Cuat | F1: Firmado | G1: LA | I1: Asignaturas | J1: Matriculados | K1: Cuatrimestre | L1: Cupo
A2: Diseño Gráfico y Animación | B2: Alumno HTU 1/2 | C2: Jordania | D2: HTU | E2: 2 | F2: x | I2: (MUII) Gestión de Auditoría y Seguridad | J2: =COUNTIF(Hoja1!A:A, I2) -> 0 | K2: 1 | L2: 5 | N2: Alu | O2: =SUM(B2:B73) -> 0
A3: Dispositivos y Redes Inalámbricos | B3: Alumno HTU 1/2 | C3: Jordania | D3: HTU | E3: 2 | F3: x | I3: (MUII) Sistemas y Servicios en la Nube | J3: =COUNTIF(Hoja1!A:A, I3) -> 0 | K3: 1 | L3: 5
A4: Fundamentos Físicos - B | B4: Alumno HTU 2/2 | C4: Jordania | D4: HTU | E4: 2 | G4: un_enlace.pdf | I4: Aceleradores Gráficos | J4: =COUNTIF(Hoja1!A:A, I4) -> 0 | K4: 2 | L4: 5
A5: Bases de Datos - I | B5: Alumno Unimore 1/9 | C5: Italia | D5: Unimore | E5: 2 | G5: un_enlace.pdf | I5: Álgebra | J5: =COUNTIF(Hoja1!A:A, I5) -> 0 | K5: 2 | L5: 5
A6: Estructura de Computadores - A | B6: Alumno Unimore 2/9 | C6: Italia | D6: Unimore | I6: Álgebra y Matemática Discreta - A | J6: =COUNTIF(Hoja1!A:A, I6) -> 0 | K6: 2 | L6: 5
A7: Fundamentos de Programación II - A | B7: Alumno Unimore 3/9 | C7: Italia | D7: Unimore | I7: Álgebra y Matemática Discreta - I | J7: =COUNTIF(Hoja1!A:A, I7) -> 0 | K7: 2 | L7: 5
A8: Comercio Electrónico | B8: Alumno Unimore 4/9 | C8: Italia | D8: Unimore | I8: Arquitectura de Computadores - I | J8: =COUNTIF(Hoja1!A:A, I8) -> 0 | K8: 1 | L8: 5
A9: Fundamentos Físicos - B | B9: Alumno Unimore 5/9 | C9: Italia | D9: Unimore | F9: x | I9: Auditoría Sistemas Información | J9: =COUNTIF(Hoja1!A:A, I9) -> 0 | K9: 1 | L9: 5
A10: Cálculo y Métodos Numéricos - I | B10: Alumno Unimore 6/9 | C10: Italia | D10: Unimore | I10: Bases de Datos - A | J10: =COUNTIF(Hoja1!A:A, I10) -> 0 | K10: 2 | L10: 5
A11: (MUII) Sistemas y Servicios en la Nube | B11: Alumno Unimore 7/9 | C11: Italia | D11: Unimore | I11: Bases de Datos - I | J11: =COUNTIF(Hoja1!A:A, I11) -> 0 | K11: 2 | L11: 5
A12: Dispositivos y Redes Inalámbricos | B12: Alumno Unimore 8/9 | C12: Italia | D12: Unimore | I12: Cálculo y Métodos Numéricos - I | J12: =COUNTIF(Hoja1!A:A, I12) -> 0 | K12: 1 | L12: 5
A13: Gestión de proyectos software | B13: Alumno Unimore 9/9 | C13: Italia | D13: Unimore | E13: 2 | F13: x | G13: Petra.pdf | I13: Calidad de los Sistemas SW | J13: =COUNTIF(Hoja1!A:A, I13) -> 0 | K13: 1 | L13: 5
A14: Fundamentos Físicos - B | B14: Alumno Bonn-Rhein-Sieg 1/2 | C14: Alemania | D14: Bonn-Rhein-Sieg | E14: 2 | F14: x | G14: Petra2.pdf | I14: Comercio Electrónico | J14: =COUNTIF(Hoja1!A:A, I14) -> 0 | K14: 1 | L14: 5
A15: Fundamentos Físicos - I | B15: Alumno Bonn-Rhein-Sieg 2/2 | C15: Alemania | D15: Bonn-Rhein-Sieg | F15: x | I15: Criptografía | J15: =COUNTIF(Hoja1!A:A, I15) -> 0 | K15: 2 | L15: 5
A16: Fundamentos Físicos - B | B16: Alumno UMAG 1/1 | C16: Chile | D16: UMAG | E16: 2 | F16: x | G16: C:UsersmariaDownloadsOSSRequestForm-v4.xlsx | I16: Diseño de Sistemas Interactivos | J16: =COUNTIF(Hoja1!A:A, I16) -> 0 | K16: 1 | L16: 5
A17: Fundamentos Físicos - B | B17: Alumno Duoc 1/1 | C17: Chile | D17: Duoc UC - Plaza Norte | I17: Diseño de Software | J17: =COUNTIF(Hoja1!A:A, I17) -> 0 | K17: 2 | L17: 5
A18: Fundamentos Físicos - B | B18: Alumno Universidad Libre 1/1 | C18: Colombia | D18: Universidad Libre | I18: Diseño Gráfico y Animación | J18: =COUNTIF(Hoja1!A:A, I18) -> 0 | K18: 2 | L18: 5
A19: Calidad de los Sistemas SW | B19: Alumno ESAIP 1/3 | C19: Francia | D19: ESAIP | I19: Dispositivos y Redes Inalámbricos | J19: =COUNTIF(Hoja1!A:A, I19) -> 0 | K19: 2 | L19: 5
A20: Diseño de Software | B20: Alumno ESAIP 2/3 | C20: Francia | D20: ESAIP | I20: Estadística - I | J20: =COUNTIF(Hoja1!A:A, I20) -> 0 | K20: 2 | L20: 5
A21: fgbvertb | B21: Alumno ESAIP 3/3 | C21: Francia | D21: ESAIP | I21: Estructura de Computadores - A | J21: =COUNTIF(Hoja1!A:A, I21) -> 0 | K21: 2 | L21: 5
A22: Estancia Investigación | B22: Alumno Business 1/4 | C22: Georgia | D22: Business and Technology University | I22: Estructura de Computadores - I | J22: =COUNTIF(Hoja1!A:A, I22) -> 0 | K22: 2 | L22: 5
A23: (MUII) Gestión de Auditoría y Seguridad | B23: Alumno Business 2/4 | C23: Georgia | D23: Business and Technology University | I23: Estructura de Datos - A | J23: =COUNTIF(Hoja1!A:A, I23) -> 0 | K23: 1 | L23: 5
A24: Diseño Gráfico y Animación | B24: Alumno Business 3/4 | C24: Georgia | D24: Business and Technology University | I24: Estructura de Datos - I | J24: =COUNTIF(Hoja1!A:A, I24) -> 0 | K24: 1 | L24: 5
A25: Organización de Computadores - I | B25: Alumno Business 4/4 | C25: Georgia | D25: Business and Technology University | I25: Fundamentos de Gestión Empresarial - A | J25: =COUNTIF(Hoja1!A:A, I25) -> 0 | K25: 1 | L25: 5
A26: Aceleradores Gráficos | B26: Alumno Udine 1/2 | C26: Italia | D26: Udine | I26: Fundamentos de Gestión Empresarial - B | J26: =COUNTIF(Hoja1!A:A, I26) -> 0 | K26: 1 | L26: 5
A27: Estadística - I | B27: Alumno Udine 2/2 | C27: Italia | D27: Udine | I27: Fundamentos de Gestión Empresarial - C | J27: =COUNTIF(Hoja1!A:A, I27) -> 0 | K27: 1 | L27: 5
A28: Gestión de Sistemas de información | B28: Alumno Udine 2/2 | C28: Italia | D28: Udine | I28: Fundamentos de Gestión Empresarial - I | J28: =COUNTIF(Hoja1!A:A, I28) -> 0 | K28: 1 | L28: 5
... A34: Álgebra y Matemática Discreta - A | B34: Alumno Sassari 1/2 | C34: Italia | D34: Degli Studi di Sassari | I34: Fundamentos Físicos - I | J34: =COUNTIF(Hoja1!A:A, I34) -> 0 | K34: 1 | L34: 5
A35: Estructura de Computadores - I | B35: Alumno Sassari 2/2 | C35: Italia | D35: Degli Studi di Sassari | E35: 1 | F35: x | I35: Gestión de proyectos software | J35: =COUNTIF(Hoja1!A:A, I35) -> 0 | K35: 1 | L35: 5
A36: Ingeniería del Software II - I | B36: Alumno Sassari 2/2 | C36: Italia | D36: Degli Studi di Sassari | E36: 1 | F36: x | I36: Gestión de Sistemas de información | J36: =COUNTIF(Hoja1!A:A, I36) -> 0 | K36: 2 | L36: 5
A37: Programación Concurrente y Tiempo Real | B37: Alumno Sassari 2/2 | C37: Italia | D37: Degli Studi di Sassari | E37: 1 | F37: x | I37: Ingeniería del Software I - I | J37: =COUNTIF(Hoja1!A:A, I37) -> 0 | K37: 1 | L37: 7
A38: Álgebra y Matemática Discreta - I | B38: Alumno Petra 1/3 | C38: Jordania | D38: University of Petra | I38: Ingeniería del Software II - I | J38: =COUNTIF(Hoja1!A:A, I38) -> 0 | K38: 1 | L38: 5
A39: Estructura de Datos - A | B39: Alumno Petra 2/3 | C39: Jordania | D39: University of Petra | I39: Ingeniería Web y de Servicios | J39: =COUNTIF(Hoja1!A:A, I39) -> 0 | K39: 1 | L39: 5
A40: Ingeniería Web y de Servicios | B40: Alumno Petra 3/3 | C40: Jordania | D40: University of Petra | I40: Inteligencia Artificial en Videojuegos | J40: =COUNTIF(Hoja1!A:A, I40) -> 0 | K40: 2 | L40: 5
A41: Programación Declarativa | B41: Alumno Petra 3/3 | C41: Jordania | D41: University of Petra | I41: Interacción Persona Ordenador I - A | J41: =COUNTIF(Hoja1!A:A, I41) -> 0 | K41: 1 | L41: 5
A42: Arquitectura de Computadores - I | B42: Alumno Yarmouk 1/2 | C42: Jordania | D42: Yarmouk University | I42: Interacción Persona Ordenador I - B | J42: =COUNTIF(Hoja1!A:A, I42) -> 0 | K42: 1 | L42: 5
A43: Estructura de Datos - I | B43: Alumno Yarmouk 1/2 | C43: Jordania | D43: Yarmouk University | I43: Interacción Persona Ordenador I - I | J43: =COUNTIF(Hoja1!A:A, I43) -> 0 | K43: 1 | L43: 7
A44: Inteligencia Artificial en Videojuegos | B44: Alumno Yarmouk 2/2 | C44: Jordania | D44: Yarmouk University | I44: Lógica - B | J44: =COUNTIF(Hoja1!A:A, I44) -> 0 | K44: 1 | L44: 5
A45: Redes de Computadores I - A | B45: Alumno Yarmouk 2/2 | C45: Jordania | D45: Yarmouk University | I45: Lógica - I | J45: =COUNTIF(Hoja1!A:A, I45) -> 0 | K45: 1 | L45: 5
...

Sheet Hoja1
A1: Columna1 | B1: Columna2 | C1: Columna3 | D1: Columna4 | E1: Columna5 | F1: Columna6 | G1: Columna7

Sheet 2024-2025
A1: Asignatura | B1: Estudiante | C1: Origen | D1: Universidad Origen | E1: Cuat | F1: Firmado | G1: LA | I1: Asignaturas | J1: Matriculados | K1: Cuatrimestre | L1: Cupo
A2: Calidad de los Sistemas SW | B2: Prueba 1 Alu | C2: Italia | D2: Pol. Milan | E2: 1 | I2: 1 | J2: 1 | K2: 1 | L2: 2
A3: Diseño de Sistemas Interactivos | B3: Prueba 1 Alu | C3: Italia | D3: Pol. Milan | E3: 1 | I3: 2 | J3: 2 | K3: 1 | L3: 2
A4: 1 | B4: Prueba 1 Alu | C4: Italia | D4: Pol. Milan | E4: 1 | I4: 3 | J4: 1 | K4: 2 | L4: 2
I5: 4 | J5: 1 | K5: 2 | L5: 2
